<mujoco model="linkerhand_O6_right.urdf">
  <compiler angle="radian" autolimits="true"/>
  <size/>
  <default/>
  <asset>
  <!-- 蓝白棋盘纹理 -->
    <texture name="grid_tex" type="2d" builtin="checker" rgb1="0.2 0.3 0.8" rgb2="1 1 1" width="512" height="512"/>
    
    <!-- 关联纹理的材质 -->
    <material name="grid_material" texture="grid_tex" texrepeat="10 10" specular="0.3" shininess="0.5"/>
    <mesh name="hand_base_link" file="hand_base_link.STL"/>
    <mesh name="thumb_metacarpals_base2" file="thumb_metacarpals_base2.STL"/>
    <mesh name="thumb_metacarpals" file="thumb_metacarpals.STL"/>
    <mesh name="thumb_distal" file="thumb_distal.STL"/>
    <mesh name="index_proximal" file="index_proximal.STL"/>
    <mesh name="index_distal" file="index_distal.STL"/>
    <mesh name="middle_proximal" file="middle_proximal.STL"/>
    <mesh name="middle_distal" file="middle_distal.STL"/>
    <mesh name="ring_proximal" file="ring_proximal.STL"/>
    <mesh name="ring_distal" file="ring_distal.STL"/>
    <mesh name="pinky_proximal" file="pinky_proximal.STL"/>
    <mesh name="pinky_distal" file="pinky_distal.STL"/>
  </asset>
  <visual>
        <quality shadowsize="4096"/>
        <map znear="0.05"/>
        <global offwidth="1280" offheight="720"/>
    </visual>

  <default>
    <joint limited="true" damping="0.1" armature="0.01"/>
    <motor ctrllimited="true"/>
    <geom condim="3" contype="1" conaffinity="1" solref="0.01 1" solimp="0.9 0.95 0.001" friction="1.0 0.005 0.0001"/>
    <equality solref="0.01 1"/>
  </default>
  <worldbody>
  <!-- 蓝白方格地面 -->
    <geom 
    name="floor" 
    type="plane" 
    pos="0 0 0" 
    size="5 5 0.1" 
    material="grid_material"
    conaffinity="1" 
    condim="3"
    />
    <geom type="mesh" rgba="1 0.6 0 1" mesh="hand_base_link"/>
    <body name="thumb_metacarpals_base2" pos="0.011508 0.022975 0.032794">
      <inertial pos="0.00162796 0.00276672 -0.00184228" quat="0.958658 0.114191 -0.0354615 -0.258221" mass="0.00138591" diaginertia="5.49427e-08 4.70357e-08 2.7769e-08"/>
      <joint name="thumb_cmc_yaw" pos="0 0 0" axis="0 0 -1" range="0 1.54"/>
      <geom type="mesh" rgba="0.164706 0.282353 0.443137 1" mesh="thumb_metacarpals_base2"/>
      <body name="thumb_metacarpals" pos="0.0061649 0.010678 -0.004891" quat="0.4192 -0.472029 -0.272524 -0.726079">
        <inertial pos="4.24921e-05 -1.67886e-05 0.0228342" quat="0.687228 -0.164922 -0.164643 0.688049" mass="0.0123382" diaginertia="1.76758e-06 1.16101e-06 8.78264e-07"/>
        <joint name="thumb_cmc_pitch" pos="0 0 0" axis="0 1 0" range="0 0.52"/>
        <geom type="mesh" rgba="1 0.6 0 1" mesh="thumb_metacarpals"/>
        <body name="thumb_distal" pos="0.0037776 0 0.045368">
          <inertial pos="-0.00413691 -4.54843e-07 0.0230097" quat="0.999397 9.12706e-06 -0.0347342 -8.13325e-06" mass="0.00763303" diaginertia="1.31047e-06 1.22457e-06 2.72295e-07"/>
          <joint name="thumb_ip" pos="0 0 0" axis="0 1 0" range="0 0.96"/>
          <geom type="mesh" rgba="0.792157 0.792157 0.792157 1" mesh="thumb_distal"/>
        </body>
      </body>
    </body>
    <body name="index_proximal" pos="0.0024758 0.02419 0.098779" quat="0.999657 -0.026177 0 0">
      <inertial pos="-0.00208666 -4.8965e-06 0.0172737" quat="0.993795 0.000369213 -0.111225 0.0007939" mass="0.00253179" diaginertia="2.75761e-07 2.72916e-07 7.58316e-08"/>
      <joint name="index_mcp_pitch" pos="0 0 0" axis="0 1 0" range="0 1.57"/>
      <geom type="mesh" rgba="0.980392 0.780392 0.627451 1" mesh="index_proximal"/>
      <body name="index_distal" pos="-0.0052516 0 0.036625">
        <inertial pos="0.0065894 -4.59977e-06 0.0194434" quat="0.97709 0.000756952 0.212768 0.00487986" mass="0.00376787" diaginertia="3.74403e-07 3.65131e-07 7.19711e-08"/>
        <joint name="index_dip" pos="0 0 0" axis="0 1 0" range="0 1.4"/>
        <geom type="mesh" rgba="0.164706 0.282353 0.443137 1" mesh="index_distal"/>
      </body>
    </body>
    <body name="middle_proximal" pos="0.00052576 0.00634 0.1027">
      <inertial pos="-0.00208661 -4.93452e-06 0.0172737" quat="0.993795 0.000375852 -0.111225 0.000731327" mass="0.00253175" diaginertia="2.75761e-07 2.72915e-07 7.58309e-08"/>
      <joint name="middle_mcp_pitch" pos="0 0 0" axis="0 1 0" range="0 1.57"/>
      <geom type="mesh" rgba="0.164706 0.282353 0.443137 1" mesh="middle_proximal"/>
      <body name="middle_distal" pos="-0.0052516 0 0.036625">
        <inertial pos="0.0065894 -4.58857e-06 0.0194435" quat="0.97709 0.000755208 0.212768 0.00486939" mass="0.00376786" diaginertia="3.74402e-07 3.6513e-07 7.19708e-08"/>
        <joint name="middle_dip" pos="0 0 0" axis="0 1 0" range="0 1.4"/>
        <geom type="mesh" rgba="0.164706 0.282353 0.443137 1" mesh="middle_distal"/>
      </body>
    </body>
    <body name="ring_proximal" pos="0.0010258 -0.011135 0.098767" quat="0.999657 0.026177 0 0">
      <inertial pos="-0.00208654 -4.98539e-06 0.0172737" quat="0.993795 0.000384813 -0.111226 0.000649851" mass="0.00253171" diaginertia="2.7576e-07 2.72915e-07 7.58301e-08"/>
      <joint name="ring_mcp_pitch" pos="0 0 0" axis="0 1 0" range="0 1.57"/>
      <geom type="mesh" rgba="0.980392 0.780392 0.627451 1" mesh="ring_proximal"/>
      <body name="ring_distal" pos="-0.0052516 0 0.036625">
        <inertial pos="0.0065894 -4.56629e-06 0.0194435" quat="0.97709 0.000751861 0.21277 0.00484872" mass="0.00376784" diaginertia="3.744e-07 3.65127e-07 7.197e-08"/>
        <joint name="ring_dip" pos="0 0 0" axis="0 1 0" range="0 1.4"/>
        <geom type="mesh" rgba="0.164706 0.282353 0.443137 1" mesh="ring_distal"/>
      </body>
    </body>
    <body name="pinky_proximal" pos="0.0024758 -0.028372 0.092741" quat="0.999048 0.0436192 0 0">
      <inertial pos="-0.00208649 -5.02315e-06 0.0172737" quat="0.993795 0.0003914 -0.111226 0.000590247" mass="0.00253167" diaginertia="2.7576e-07 2.72914e-07 7.58294e-08"/>
      <joint name="pinky_mcp_pitch" pos="0 0 0" axis="0 1 0" range="0 1.57"/>
      <geom type="mesh" rgba="0.980392 0.780392 0.627451 1" mesh="pinky_proximal"/>
      <body name="pinky_distal" pos="-0.0052516 0 0.036625">
        <inertial pos="0.0065894 -4.55268e-06 0.0194435" quat="0.97709 0.000749893 0.21277 0.00483566" mass="0.00376783" diaginertia="3.74398e-07 3.65126e-07 7.19694e-08"/>
        <joint name="pinky_dip" pos="0 0 0" axis="0 1 0" range="0 1.4"/>
        <geom type="mesh" rgba="0.164706 0.282353 0.443137 1" mesh="pinky_distal"/>
      </body>
    </body>
  </worldbody>
  <actuator>
    <position name="thumb_pos0" joint="thumb_cmc_yaw" kp="10" ctrlrange="0 1.54"/>
    <position name="thumb_pos1" joint="thumb_cmc_pitch" kp="10" ctrlrange="0 0.52"/>
    <position name="thumb_pos2" joint="thumb_ip" kp="10" ctrlrange="0 0.96"/>

    
    <position name="index_pos1" joint="index_mcp_pitch" kp="10" ctrlrange="0 1.57"/>
    <position name="index_pos2" joint="index_dip" kp="10" ctrlrange="0 1.40"/>

    
    <position name="middle_pos0" joint="middle_mcp_pitch" kp="10" ctrlrange="0 1.57"/>
    <position name="middle_pos1" joint="middle_dip" kp="10" ctrlrange="0 1.40"/>



    <position name="ring_pos1" joint="ring_mcp_pitch" kp="10" ctrlrange="0 1.57"/>
    <position name="ring_pos2" joint="ring_dip" kp="10" ctrlrange="0 1.40"/>


    <position name="little_pos1" joint="pinky_mcp_pitch" kp="10" ctrlrange="0 1.57"/>
    <position name="little_pos2" joint="pinky_dip" kp="10" ctrlrange="0 1.40"/>

  </actuator>
</mujoco>
